<mujoco model="kbotv2p0_headless">
  <default>
    <default class="robot">
      <default class="robstride_04">
        <joint armature="0.04" frictionloss="0.2" actuatorfrcrange="-120.0 120.0" />
        <motor ctrlrange="-120.0 120.0" />
      </default>
      <default class="robstride_03">
        <joint armature="0.02" frictionloss="0.2" actuatorfrcrange="-60.0 60.0" />
        <motor ctrlrange="-60.0 60.0" />
      </default>
      <default class="robstride_00">
        <joint armature="0.001" frictionloss="0.1" actuatorfrcrange="-14.0 14.0" />
        <motor ctrlrange="-14.0 14.0" />
      </default>
      <default class="robstride_02">
        <joint armature="0.0042" frictionloss="0.1" actuatorfrcrange="-17.0 17.0" />
        <motor ctrlrange="-17.0 17.0" />
      </default>
      <default class="visual">
        <geom material="visualgeom" contype="0" conaffinity="0" group="2" />
      </default>
      <default class="collision">
        <geom material="collision_material" condim="3" contype="0" conaffinity="1" priority="1" group="1" solref="0.005 1" friction="0.64" />
        <equality solimp="0.99 0.999 1e-05" solref="0.005 1" />
      </default>
    </default>
    <mesh maxhullvert="64" />
  </default>

  <compiler angle="radian" />

  <asset>
    <material name="base_material" rgba="1 0 0 1" />
    <material name="Torso_Side_Right_material" rgba="0.098039 0.098039 0.098039 1" />
    <material name="imu_material" rgba="0.231373 0.380392 0.705882 1" />
    <material name="default_material" rgba="0.7 0.7 0.7 1" />
    <material name="collision_material" rgba="1.0 0.28 0.1 0.9" />
    <mesh name="Torso_Side_Right_collision.stl" file="meshes/Torso_Side_Right_collision.stl" />
    <mesh name="Torso_Side_Right.stl" file="meshes/Torso_Side_Right.stl" />
    <mesh name="KC_C_104R_PitchHardstopDriven_collision.stl" file="meshes/KC_C_104R_PitchHardstopDriven_collision.stl" />
    <mesh name="KC_C_104R_PitchHardstopDriven.stl" file="meshes/KC_C_104R_PitchHardstopDriven.stl" />
    <mesh name="RS03_3_collision.stl" file="meshes/RS03_3_collision.stl" />
    <mesh name="RS03_3.stl" file="meshes/RS03_3.stl" />
    <mesh name="KC_C_202R_collision.stl" file="meshes/KC_C_202R_collision.stl" />
    <mesh name="KC_C_202R.stl" file="meshes/KC_C_202R.stl" />
    <mesh name="KC_C_401R_R_UpForearmDrive_collision.stl" file="meshes/KC_C_401R_R_UpForearmDrive_collision.stl" />
    <mesh name="KC_C_401R_R_UpForearmDrive.stl" file="meshes/KC_C_401R_R_UpForearmDrive.stl" />
    <mesh name="KB_C_501X_Right_Bayonet_Adapter_Hard_Stop_collision.stl" file="meshes/KB_C_501X_Right_Bayonet_Adapter_Hard_Stop_collision.stl" />
    <mesh name="KB_C_501X_Right_Bayonet_Adapter_Hard_Stop.stl" file="meshes/KB_C_501X_Right_Bayonet_Adapter_Hard_Stop.stl" />
    <mesh name="imu_collision.stl" file="meshes/imu_collision.stl" />
    <mesh name="imu.stl" file="meshes/imu.stl" />
    <mesh name="KC_C_104L_PitchHardstopDriven_collision.stl" file="meshes/KC_C_104L_PitchHardstopDriven_collision.stl" />
    <mesh name="KC_C_104L_PitchHardstopDriven.stl" file="meshes/KC_C_104L_PitchHardstopDriven.stl" />
    <mesh name="RS03_6_collision.stl" file="meshes/RS03_6_collision.stl" />
    <mesh name="RS03_6.stl" file="meshes/RS03_6.stl" />
    <mesh name="KC_C_202L_collision.stl" file="meshes/KC_C_202L_collision.stl" />
    <mesh name="KC_C_202L.stl" file="meshes/KC_C_202L.stl" />
    <mesh name="KC_C_401L_L_UpForearmDrive_collision.stl" file="meshes/KC_C_401L_L_UpForearmDrive_collision.stl" />
    <mesh name="KC_C_401L_L_UpForearmDrive.stl" file="meshes/KC_C_401L_L_UpForearmDrive.stl" />
    <mesh name="KB_C_501X_Left_Bayonet_Adapter_Hard_Stop_collision.stl" file="meshes/KB_C_501X_Left_Bayonet_Adapter_Hard_Stop_collision.stl" />
    <mesh name="KB_C_501X_Left_Bayonet_Adapter_Hard_Stop.stl" file="meshes/KB_C_501X_Left_Bayonet_Adapter_Hard_Stop.stl" />
    <mesh name="KC_D_102R_R_Hip_Yoke_Drive_collision.stl" file="meshes/KC_D_102R_R_Hip_Yoke_Drive_collision.stl" />
    <mesh name="KC_D_102R_R_Hip_Yoke_Drive.stl" file="meshes/KC_D_102R_R_Hip_Yoke_Drive.stl" />
    <mesh name="RS03_4_collision.stl" file="meshes/RS03_4_collision.stl" />
    <mesh name="RS03_4.stl" file="meshes/RS03_4.stl" />
    <mesh name="KC_D_301R_R_Femur_Lower_Drive_collision.stl" file="meshes/KC_D_301R_R_Femur_Lower_Drive_collision.stl" />
    <mesh name="KC_D_301R_R_Femur_Lower_Drive.stl" file="meshes/KC_D_301R_R_Femur_Lower_Drive.stl" />
    <mesh name="KC_D_401R_R_Shin_Drive_collision.stl" file="meshes/KC_D_401R_R_Shin_Drive_collision.stl" />
    <mesh name="KC_D_401R_R_Shin_Drive.stl" file="meshes/KC_D_401R_R_Shin_Drive.stl" />
    <mesh name="KB_D_501R_R_LEG_FOOT_collision.stl" file="meshes/KB_D_501R_R_LEG_FOOT_collision.stl" />
    <mesh name="KB_D_501R_R_LEG_FOOT.stl" file="meshes/KB_D_501R_R_LEG_FOOT.stl" />
    <mesh name="KC_D_102L_L_Hip_Yoke_Drive_collision.stl" file="meshes/KC_D_102L_L_Hip_Yoke_Drive_collision.stl" />
    <mesh name="KC_D_102L_L_Hip_Yoke_Drive.stl" file="meshes/KC_D_102L_L_Hip_Yoke_Drive.stl" />
    <mesh name="RS03_5_collision.stl" file="meshes/RS03_5_collision.stl" />
    <mesh name="RS03_5.stl" file="meshes/RS03_5.stl" />
    <mesh name="KC_D_301L_L_Femur_Lower_Drive_collision.stl" file="meshes/KC_D_301L_L_Femur_Lower_Drive_collision.stl" />
    <mesh name="KC_D_301L_L_Femur_Lower_Drive.stl" file="meshes/KC_D_301L_L_Femur_Lower_Drive.stl" />
    <mesh name="KC_D_401L_L_Shin_Drive_collision.stl" file="meshes/KC_D_401L_L_Shin_Drive_collision.stl" />
    <mesh name="KC_D_401L_L_Shin_Drive.stl" file="meshes/KC_D_401L_L_Shin_Drive.stl" />
    <mesh name="KB_D_501L_L_LEG_FOOT_collision.stl" file="meshes/KB_D_501L_L_LEG_FOOT_collision.stl" />
    <mesh name="KB_D_501L_L_LEG_FOOT.stl" file="meshes/KB_D_501L_L_LEG_FOOT.stl" />
  </asset>

  <worldbody>
    <body name="base" pos="0.00000000 0.00000000 1.01947904" quat="1 0 0 0" childclass="robot">
      <freejoint name="floating_base" />
      <geom name="base_visual" pos="0 -0.095 0" quat="0.7071054825112363 0.0 0.0 0.7071080798594735" material="base_material" type="sphere" size="0.01" class="visual" />
      <body name="Torso_Side_Right" pos="0 -0.095 0" quat="0.7071054825112363 0.0 0.0 0.7071080798594735">
        <inertial pos="0.093008 0.001559 -0.095495" quat="1.0 0.0 0.0 0.0" mass="12.368080" diaginertia="0.32902 0.355896 0.054395" />
        <geom name="Torso_Side_Right_collision" pos="0 0 0" quat="1.0 0.0 0.0 0.0" type="mesh" mesh="Torso_Side_Right_collision.stl" class="collision" />
        <geom name="Torso_Side_Right_visual" pos="0 0 0" quat="1.0 0.0 0.0 0.0" material="Torso_Side_Right_material" type="mesh" mesh="Torso_Side_Right.stl" class="visual" />
        <body name="KC_C_104R_PitchHardstopDriven" pos="-0.028031 0.000007 0.126021" quat="0.5000001633974483 0.4999999999999733 0.49999983660255165 0.4999999999999733">
          <joint name="dof_right_shoulder_pitch_03" type="hinge" ref="0.0" class="robstride_03" range="-3.141593 1.396263" axis="0 0 1" />
          <inertial pos="-0.004584 0.002745 -0.051222" quat="1.0 0.0 0.0 0.0" mass="0.584848" diaginertia="0.001182 0.001537 0.001416" />
          <geom name="KC_C_104R_PitchHardstopDriven_collision" pos="0 0 0" quat="1.0 0.0 0.0 0.0" type="mesh" mesh="KC_C_104R_PitchHardstopDriven_collision.stl" class="collision" />
          <geom name="KC_C_104R_PitchHardstopDriven_visual" pos="0 0 0" quat="1.0 0.0 0.0 0.0" material="Torso_Side_Right_material" type="mesh" mesh="KC_C_104R_PitchHardstopDriven.stl" class="visual" />
          <body name="RS03_3" pos="-0.024250 0 -0.080000" quat="-1.2247452309842457e-07 -0.7071068967259713 1.22474483074382e-07 -0.7071066656470838">
            <joint name="dof_right_shoulder_roll_03" type="hinge" ref="0.0" class="robstride_03" range="-1.658063 0.349066" axis="0 0 -1" />
            <inertial pos="-0.004944 0.042532 0.027432" quat="1.0 0.0 0.0 0.0" mass="1.676509" diaginertia="0.006831 0.001755 0.007324" />
            <geom name="RS03_3_collision" pos="0 0 0" quat="1.0 0.0 0.0 0.0" type="mesh" mesh="RS03_3_collision.stl" class="collision" />
            <geom name="RS03_3_visual" pos="0 0 0" quat="1.0 0.0 0.0 0.0" material="Torso_Side_Right_material" type="mesh" mesh="RS03_3.stl" class="visual" />
            <body name="KC_C_202R" pos="-0.013000 0.142000 0.030250" quat="0.7071068967259818 0.7071066656470943 0.0 0.0">
              <joint name="dof_right_shoulder_yaw_02" type="hinge" ref="0.0" class="robstride_02" range="-1.658063 1.658063" axis="0 0 1" />
              <inertial pos="0.003910 -0.004160 -0.101316" quat="1.0 0.0 0.0 0.0" mass="0.743508" diaginertia="0.00241 0.002208 0.000693" />
              <geom name="KC_C_202R_collision" pos="0 0 0" quat="1.0 0.0 0.0 0.0" type="mesh" mesh="KC_C_202R_collision.stl" class="collision" />
              <geom name="KC_C_202R_visual" pos="0 0 0" quat="1.0 0.0 0.0 0.0" material="Torso_Side_Right_material" type="mesh" mesh="KC_C_202R.stl" class="visual" />
              <body name="KC_C_401R_R_UpForearmDrive" pos="0.018500 -0.010000 -0.137000" quat="0.7071068967259818 0.0 0.7071066656470943 0.0">
                <joint name="dof_right_elbow_02" type="hinge" ref="0.0" class="robstride_02" range="0 2.478368" axis="0 0 -1" />
                <inertial pos="0.061999 0.015867 -0.012446" quat="1.0 0.0 0.0 0.0" mass="0.585204" diaginertia="0.000522 0.001021 0.00102" />
                <geom name="KC_C_401R_R_UpForearmDrive_collision" pos="0 0 0" quat="1.0 0.0 0.0 0.0" type="mesh" mesh="KC_C_401R_R_UpForearmDrive_collision.stl" class="collision" />
                <geom name="KC_C_401R_R_UpForearmDrive_visual" pos="0 0 0" quat="1.0 0.0 0.0 0.0" material="Torso_Side_Right_material" type="mesh" mesh="KC_C_401R_R_UpForearmDrive.stl" class="visual" />
                <body name="KB_C_501X_Right_Bayonet_Adapter_Hard_Stop" pos="0.103000 0.017350 -0.018000" quat="0.7071068967259818 0.0 -0.7071066656470943 0.0">
                  <joint name="dof_right_wrist_00" type="hinge" ref="0.0" class="robstride_00" range="-1.745329 1.745329" axis="0 0 1" />
                  <inertial pos="0.004187 0.000068 -0.019905" quat="1.0 0.0 0.0 0.0" mass="0.152198" diaginertia="6.1e-05 6.1e-05 8.4e-05" />
                  <geom name="KB_C_501X_Right_Bayonet_Adapter_Hard_Stop_collision" pos="0 0 0" quat="1.0 0.0 0.0 0.0" type="mesh" mesh="KB_C_501X_Right_Bayonet_Adapter_Hard_Stop_collision.stl" class="collision" />
                  <geom name="KB_C_501X_Right_Bayonet_Adapter_Hard_Stop_visual" pos="0 0 0" quat="1.0 0.0 0.0 0.0" material="Torso_Side_Right_material" type="mesh" mesh="KB_C_501X_Right_Bayonet_Adapter_Hard_Stop.stl" class="visual" />
                </body>
              </body>
            </body>
          </body>
        </body>
        <body name="imu" pos="0.093118 -0.000341 0.188248" quat="0.7071068967259818 0.0 0.0 -0.7071066656470943">
          <inertial pos="-0.003012 0 0.002999" quat="1.0 0.0 0.0 0.0" mass="0.005700" diaginertia="1e-06 1e-06 2e-06" />
          <geom name="imu_collision" pos="0 0 0" quat="1.0 0.0 0.0 0.0" type="mesh" mesh="imu_collision.stl" class="collision" />
          <geom name="imu_visual" pos="0 0 0" quat="1.0 0.0 0.0 0.0" material="imu_material" type="mesh" mesh="imu.stl" class="visual" />
          <site name="imu_site" quat="1.0 0.0 0.0 0.0" pos="0.0 0.0 0.0" />
        </body>
        <body name="KC_C_104L_PitchHardstopDriven" pos="0.213969 0.000007 0.126021" quat="0.5000001633974483 -0.4999999999999733 -0.49999983660255165 0.4999999999999733">
          <joint name="dof_left_shoulder_pitch_03" type="hinge" ref="0.0" class="robstride_03" range="-1.396263 3.141593" axis="0 0 1" />
          <inertial pos="-0.004595 -0.002745 -0.051222" quat="1.0 0.0 0.0 0.0" mass="0.584843" diaginertia="0.001182 0.001536 0.001415" />
          <geom name="KC_C_104L_PitchHardstopDriven_collision" pos="0 0 0" quat="1.0 0.0 0.0 0.0" type="mesh" mesh="KC_C_104L_PitchHardstopDriven_collision.stl" class="collision" />
          <geom name="KC_C_104L_PitchHardstopDriven_visual" pos="0 0 0" quat="1.0 0.0 0.0 0.0" material="Torso_Side_Right_material" type="mesh" mesh="KC_C_104L_PitchHardstopDriven.stl" class="visual" />
          <body name="RS03_6" pos="-0.024250 0 -0.080000" quat="-1.2247452309842457e-07 -0.7071068967259713 -1.22474483074382e-07 0.7071066656470838">
            <joint name="dof_left_shoulder_roll_03" type="hinge" ref="0.0" class="robstride_03" range="-0.349066 1.658063" axis="0 0 1" />
            <inertial pos="0.004944 -0.042531 -0.027433" quat="1.0 0.0 0.0 0.0" mass="1.676479" diaginertia="0.00683 0.001755 0.007324" />
            <geom name="RS03_6_collision" pos="0 0 0" quat="1.0 0.0 0.0 0.0" type="mesh" mesh="RS03_6_collision.stl" class="collision" />
            <geom name="RS03_6_visual" pos="0 0 0" quat="1.0 0.0 0.0 0.0" material="Torso_Side_Right_material" type="mesh" mesh="RS03_6.stl" class="visual" />
            <body name="KC_C_202L" pos="0.013000 -0.142000 -0.030250" quat="0.7071068967259818 0.7071066656470943 0.0 0.0">
              <joint name="dof_left_shoulder_yaw_02" type="hinge" ref="0.0" class="robstride_02" range="-1.658063 1.658063" axis="0 0 -1" />
              <inertial pos="0.000925 0.006010 0.113327" quat="1.0 0.0 0.0 0.0" mass="0.579259" diaginertia="0.001537 0.001383 0.000471" />
              <geom name="KC_C_202L_collision" pos="0 0 0" quat="1.0 0.0 0.0 0.0" type="mesh" mesh="KC_C_202L_collision.stl" class="collision" />
              <geom name="KC_C_202L_visual" pos="0 0 0" quat="1.0 0.0 0.0 0.0" material="Torso_Side_Right_material" type="mesh" mesh="KC_C_202L.stl" class="visual" />
              <body name="KC_C_401L_L_UpForearmDrive" pos="-0.018500 0.010000 0.137000" quat="-1.2247452309842457e-07 -0.7071068967259713 -1.22474483074382e-07 0.7071066656470838">
                <joint name="dof_left_elbow_02" type="hinge" ref="0.0" class="robstride_02" range="-2.478368 0" axis="0 0 -1" />
                <inertial pos="-0.061998 0.015867 -0.012446" quat="1.0 0.0 0.0 0.0" mass="0.585219" diaginertia="0.000522 0.001021 0.00102" />
                <geom name="KC_C_401L_L_UpForearmDrive_collision" pos="0 0 0" quat="1.0 0.0 0.0 0.0" type="mesh" mesh="KC_C_401L_L_UpForearmDrive_collision.stl" class="collision" />
                <geom name="KC_C_401L_L_UpForearmDrive_visual" pos="0 0 0" quat="1.0 0.0 0.0 0.0" material="Torso_Side_Right_material" type="mesh" mesh="KC_C_401L_L_UpForearmDrive.stl" class="visual" />
                <body name="KB_C_501X_Left_Bayonet_Adapter_Hard_Stop" pos="-0.103000 0.017350 -0.018000" quat="-1.2247452309842457e-07 -0.7071068967259713 -1.22474483074382e-07 0.7071066656470838">
                  <joint name="dof_left_wrist_00" type="hinge" ref="0.0" class="robstride_00" range="-1.745329 1.745329" axis="0 0 -1" />
                  <inertial pos="-0.004187 -0.000068 0.019905" quat="1.0 0.0 0.0 0.0" mass="0.152198" diaginertia="6.1e-05 6.1e-05 8.4e-05" />
                  <geom name="KB_C_501X_Left_Bayonet_Adapter_Hard_Stop_collision" pos="0 0 0" quat="1.0 0.0 0.0 0.0" type="mesh" mesh="KB_C_501X_Left_Bayonet_Adapter_Hard_Stop_collision.stl" class="collision" />
                  <geom name="KB_C_501X_Left_Bayonet_Adapter_Hard_Stop_visual" pos="0 0 0" quat="1.0 0.0 0.0 0.0" material="Torso_Side_Right_material" type="mesh" mesh="KB_C_501X_Left_Bayonet_Adapter_Hard_Stop.stl" class="visual" />
                </body>
              </body>
            </body>
          </body>
        </body>
        <body name="KC_D_102R_R_Hip_Yoke_Drive" pos="0.037469 0.000007 -0.284479" quat="0.5000001633974483 0.4999999999999733 0.49999983660255165 0.4999999999999733">
          <joint name="dof_right_hip_pitch_04" type="hinge" ref="0.0" class="robstride_04" range="-2.216568 1.047198" axis="0 0 1" />
          <inertial pos="-0.005644 -0.004227 -0.038197" quat="1.0 0.0 0.0 0.0" mass="0.530428" diaginertia="0.00088 0.001182 0.001271" />
          <geom name="KC_D_102R_R_Hip_Yoke_Drive_collision" pos="0 0 0" quat="1.0 0.0 0.0 0.0" type="mesh" mesh="KC_D_102R_R_Hip_Yoke_Drive_collision.stl" class="collision" />
          <geom name="KC_D_102R_R_Hip_Yoke_Drive_visual" pos="0 0 0" quat="1.0 0.0 0.0 0.0" material="Torso_Side_Right_material" type="mesh" mesh="KC_D_102R_R_Hip_Yoke_Drive.stl" class="visual" />
          <body name="RS03_4" pos="-0.028250 -0.030000 -0.071000" quat="-1.2247452309842457e-07 0.7071068967259713 1.22474483074382e-07 0.7071066656470838">
            <joint name="dof_right_hip_roll_03" type="hinge" ref="0.0" class="robstride_03" range="-2.268928 0.209440" axis="0 0 -1" />
            <inertial pos="-0.000249 0.058017 0.025580" quat="1.0 0.0 0.0 0.0" mass="2.373184" diaginertia="0.010217 0.003255 0.010667" />
            <geom name="RS03_4_collision" pos="0 0 0" quat="1.0 0.0 0.0 0.0" type="mesh" mesh="RS03_4_collision.stl" class="collision" />
            <geom name="RS03_4_visual" pos="0 0 0" quat="1.0 0.0 0.0 0.0" material="Torso_Side_Right_material" type="mesh" mesh="RS03_4.stl" class="visual" />
            <body name="KC_D_301R_R_Femur_Lower_Drive" pos="0 0.143000 0.024250" quat="0.7071068967259818 -0.7071066656470943 0.0 0.0">
              <joint name="dof_right_hip_yaw_03" type="hinge" ref="0.0" class="robstride_03" range="-1.570796 1.570796" axis="0 0 -1" />
              <inertial pos="-0.001014 -0.013387 0.171456" quat="1.0 0.0 0.0 0.0" mass="2.343635" diaginertia="0.015645 0.014172 0.004016" />
              <geom name="KC_D_301R_R_Femur_Lower_Drive_collision" pos="0 0 0" quat="1.0 0.0 0.0 0.0" type="mesh" mesh="KC_D_301R_R_Femur_Lower_Drive_collision.stl" class="collision" />
              <geom name="KC_D_301R_R_Femur_Lower_Drive_visual" pos="0 0 0" quat="1.0 0.0 0.0 0.0" material="Torso_Side_Right_material" type="mesh" mesh="KC_D_301R_R_Femur_Lower_Drive.stl" class="visual" />
              <body name="KC_D_401R_R_Shin_Drive" pos="0.020500 -0.021000 0.212000" quat="0.5000001633974483 0.4999999999999733 -0.49999983660255165 -0.4999999999999733">
                <joint name="dof_right_knee_04" type="hinge" ref="0.0" class="robstride_04" range="-2.705260 0" axis="0 0 1" />
                <inertial pos="-0.024549 0.104152 0.018182" quat="1.0 0.0 0.0 0.0" mass="1.670592" diaginertia="0.014672 0.002924 0.014592" />
                <geom name="KC_D_401R_R_Shin_Drive_collision" pos="0 0 0" quat="1.0 0.0 0.0 0.0" type="mesh" mesh="KC_D_401R_R_Shin_Drive_collision.stl" class="collision" />
                <geom name="KC_D_401R_R_Shin_Drive_visual" pos="0 0 0" quat="1.0 0.0 0.0 0.0" material="Torso_Side_Right_material" type="mesh" mesh="KC_D_401R_R_Shin_Drive.stl" class="visual" />
                <body name="KB_D_501R_R_LEG_FOOT" pos="-0.030000 0.290000 0.035100" quat="1.0 0.0 0.0 0.0">
                  <joint name="dof_right_ankle_02" type="hinge" ref="0.0" class="robstride_02" range="-0.226893 1.256637" axis="0 0 1" />
                  <inertial pos="-0.017200 0.031958 -0.015781" quat="1.0 0.0 0.0 0.0" mass="0.601661" diaginertia="0.000357 0.001944 0.00188" />
                  <geom name="KB_D_501R_R_LEG_FOOT_visual" pos="0 0 0" quat="1.0 0.0 0.0 0.0" material="Torso_Side_Right_material" type="mesh" mesh="KB_D_501R_R_LEG_FOOT.stl" class="visual" />
                  <geom name="KB_D_501R_R_LEG_FOOT_collision_capsule_0" type="capsule" quat="1.000000 0.000000 0.000000 0.000000" fromto="-0.113899 0.038000 -0.029830 0.056761 0.038000 -0.029830" size="0.020000 0.105330" material="collision_material" class="collision" />
                  <geom name="KB_D_501R_R_LEG_FOOT_visual_capsule_0" type="capsule" quat="1.000000 0.000000 0.000000 0.000000" fromto="-0.113899 0.038000 -0.029830 0.056761 0.038000 -0.029830" size="0.020000 0.105330" material="Torso_Side_Right_material" class="visual" />
                  <geom name="KB_D_501R_R_LEG_FOOT_collision_capsule_1" type="capsule" quat="1.000000 0.000000 0.000000 0.000000" fromto="-0.107318 0.038000 0.002000 0.055951 0.038000 0.002000" size="0.020000 0.105330" material="collision_material" class="collision" />
                  <geom name="KB_D_501R_R_LEG_FOOT_visual_capsule_1" type="capsule" quat="1.000000 0.000000 0.000000 0.000000" fromto="-0.107318 0.038000 0.002000 0.055951 0.038000 0.002000" size="0.020000 0.105330" material="Torso_Side_Right_material" class="visual" />
                  <site name="right_foot" size="0.105 0.02 0.036" pos="-0.0283 0.038 -0.014" type="box" />
                </body>
              </body>
            </body>
          </body>
        </body>
        <body name="KC_D_102L_L_Hip_Yoke_Drive" pos="0.147969 0.000007 -0.284479" quat="0.5000001633974483 -0.4999999999999733 -0.49999983660255165 0.4999999999999733">
          <joint name="dof_left_hip_pitch_04" type="hinge" ref="0.0" class="robstride_04" range="-1.047198 2.216568" axis="0 0 1" />
          <inertial pos="-0.005644 0.004227 -0.038197" quat="1.0 0.0 0.0 0.0" mass="0.530424" diaginertia="0.00088 0.001182 0.001271" />
          <geom name="KC_D_102L_L_Hip_Yoke_Drive_collision" pos="0 0 0" quat="1.0 0.0 0.0 0.0" type="mesh" mesh="KC_D_102L_L_Hip_Yoke_Drive_collision.stl" class="collision" />
          <geom name="KC_D_102L_L_Hip_Yoke_Drive_visual" pos="0 0 0" quat="1.0 0.0 0.0 0.0" material="Torso_Side_Right_material" type="mesh" mesh="KC_D_102L_L_Hip_Yoke_Drive.stl" class="visual" />
          <body name="RS03_5" pos="-0.028250 0.030000 -0.071000" quat="0.7071068967259818 0.0 0.7071066656470943 0.0">
            <joint name="dof_left_hip_roll_03" type="hinge" ref="0.0" class="robstride_03" range="-0.209440 2.268928" axis="0 0 -1" />
            <inertial pos="0.000249 0.058017 0.025578" quat="1.0 0.0 0.0 0.0" mass="2.373239" diaginertia="0.010217 0.003255 0.010667" />
            <geom name="RS03_5_collision" pos="0 0 0" quat="1.0 0.0 0.0 0.0" type="mesh" mesh="RS03_5_collision.stl" class="collision" />
            <geom name="RS03_5_visual" pos="0 0 0" quat="1.0 0.0 0.0 0.0" material="Torso_Side_Right_material" type="mesh" mesh="RS03_5.stl" class="visual" />
            <body name="KC_D_301L_L_Femur_Lower_Drive" pos="0 0.143000 0.024250" quat="0.7071068967259818 -0.7071066656470943 0.0 0.0">
              <joint name="dof_left_hip_yaw_03" type="hinge" ref="0.0" class="robstride_03" range="-1.570796 1.570796" axis="0 0 -1" />
              <inertial pos="0.001013 -0.013386 0.171458" quat="1.0 0.0 0.0 0.0" mass="2.343629" diaginertia="0.015644 0.014172 0.004016" />
              <geom name="KC_D_301L_L_Femur_Lower_Drive_collision" pos="0 0 0" quat="1.0 0.0 0.0 0.0" type="mesh" mesh="KC_D_301L_L_Femur_Lower_Drive_collision.stl" class="collision" />
              <geom name="KC_D_301L_L_Femur_Lower_Drive_visual" pos="0 0 0" quat="1.0 0.0 0.0 0.0" material="Torso_Side_Right_material" type="mesh" mesh="KC_D_301L_L_Femur_Lower_Drive.stl" class="visual" />
              <body name="KC_D_401L_L_Shin_Drive" pos="-0.020500 -0.021000 0.212000" quat="0.5000001633974483 -0.4999999999999733 0.49999983660255165 -0.4999999999999733">
                <joint name="dof_left_knee_04" type="hinge" ref="0.0" class="robstride_04" range="0 2.705260" axis="0 0 1" />
                <inertial pos="-0.024550 -0.104154 0.018183" quat="1.0 0.0 0.0 0.0" mass="1.670535" diaginertia="0.014672 0.002924 0.014592" />
                <geom name="KC_D_401L_L_Shin_Drive_collision" pos="0 0 0" quat="1.0 0.0 0.0 0.0" type="mesh" mesh="KC_D_401L_L_Shin_Drive_collision.stl" class="collision" />
                <geom name="KC_D_401L_L_Shin_Drive_visual" pos="0 0 0" quat="1.0 0.0 0.0 0.0" material="Torso_Side_Right_material" type="mesh" mesh="KC_D_401L_L_Shin_Drive.stl" class="visual" />
                <body name="KB_D_501L_L_LEG_FOOT" pos="-0.030000 -0.290000 0.035100" quat="-1.7320510330969933e-07 -0.999999999999985 -0.0 0.0">
                  <joint name="dof_left_ankle_02" type="hinge" ref="0.0" class="robstride_02" range="-1.256637 0.226893" axis="0 0 -1" />
                  <inertial pos="-0.017203 0.031964 0.015780" quat="1.0 0.0 0.0 0.0" mass="0.601886" diaginertia="0.000357 0.001945 0.001881" />
                  <geom name="KB_D_501L_L_LEG_FOOT_visual" pos="0 0 0" quat="1.0 0.0 0.0 0.0" material="Torso_Side_Right_material" type="mesh" mesh="KB_D_501L_L_LEG_FOOT.stl" class="visual" />
                  <geom name="KB_D_501L_L_LEG_FOOT_collision_capsule_0" type="capsule" quat="1.000000 0.000000 0.000000 0.000000" fromto="-0.100321 0.037847 -0.002000 0.056310 0.037847 -0.002000" size="0.020000 0.105104" material="collision_material" class="collision" />
                  <geom name="KB_D_501L_L_LEG_FOOT_visual_capsule_0" type="capsule" quat="1.000000 0.000000 0.000000 0.000000" fromto="-0.100321 0.037847 -0.002000 0.056310 0.037847 -0.002000" size="0.020000 0.105104" material="Torso_Side_Right_material" class="visual" />
                  <geom name="KB_D_501L_L_LEG_FOOT_collision_capsule_1" type="capsule" quat="1.000000 0.000000 0.000000 0.000000" fromto="-0.113899 0.037847 0.029830 0.055951 0.037847 0.029830" size="0.020000 0.105104" material="collision_material" class="collision" />
                  <geom name="KB_D_501L_L_LEG_FOOT_visual_capsule_1" type="capsule" quat="1.000000 0.000000 0.000000 0.000000" fromto="-0.113899 0.037847 0.029830 0.055951 0.037847 0.029830" size="0.020000 0.105104" material="Torso_Side_Right_material" class="visual" />
                  <site name="left_foot" size="0.105 0.02 0.036" pos="-0.0283 0.038 0.014" type="box" />
                </body>
              </body>
            </body>
          </body>
        </body>
      </body>
      <site name="base_site" pos="0 0 0" quat="1 0 0 0" />
      <camera name="front_camera" mode="track" fovy="90.0" quat="4.329780281177467e-17 4.329780281177466e-17 0.7071067811865475 0.7071067811865476" pos="0.0 2.0 0.5" />
      <camera name="side_camera" mode="track" fovy="90.0" quat="-0.5 -0.4999999999999999 0.5 0.5000000000000001" pos="-2.0 0.0 0.5" />
    </body>
  </worldbody>

  <actuator>
    <motor name="dof_right_shoulder_pitch_03_ctrl" joint="dof_right_shoulder_pitch_03" class="robstride_03" />
    <motor name="dof_right_shoulder_roll_03_ctrl" joint="dof_right_shoulder_roll_03" class="robstride_03" />
    <motor name="dof_right_shoulder_yaw_02_ctrl" joint="dof_right_shoulder_yaw_02" class="robstride_02" />
    <motor name="dof_right_elbow_02_ctrl" joint="dof_right_elbow_02" class="robstride_02" />
    <motor name="dof_right_wrist_00_ctrl" joint="dof_right_wrist_00" class="robstride_00" />
    <motor name="dof_left_shoulder_pitch_03_ctrl" joint="dof_left_shoulder_pitch_03" class="robstride_03" />
    <motor name="dof_left_shoulder_roll_03_ctrl" joint="dof_left_shoulder_roll_03" class="robstride_03" />
    <motor name="dof_left_shoulder_yaw_02_ctrl" joint="dof_left_shoulder_yaw_02" class="robstride_02" />
    <motor name="dof_left_elbow_02_ctrl" joint="dof_left_elbow_02" class="robstride_02" />
    <motor name="dof_left_wrist_00_ctrl" joint="dof_left_wrist_00" class="robstride_00" />
    <motor name="dof_right_hip_pitch_04_ctrl" joint="dof_right_hip_pitch_04" class="robstride_04" />
    <motor name="dof_right_hip_roll_03_ctrl" joint="dof_right_hip_roll_03" class="robstride_03" />
    <motor name="dof_right_hip_yaw_03_ctrl" joint="dof_right_hip_yaw_03" class="robstride_03" />
    <motor name="dof_right_knee_04_ctrl" joint="dof_right_knee_04" class="robstride_04" />
    <motor name="dof_right_ankle_02_ctrl" joint="dof_right_ankle_02" class="robstride_02" />
    <motor name="dof_left_hip_pitch_04_ctrl" joint="dof_left_hip_pitch_04" class="robstride_04" />
    <motor name="dof_left_hip_roll_03_ctrl" joint="dof_left_hip_roll_03" class="robstride_03" />
    <motor name="dof_left_hip_yaw_03_ctrl" joint="dof_left_hip_yaw_03" class="robstride_03" />
    <motor name="dof_left_knee_04_ctrl" joint="dof_left_knee_04" class="robstride_04" />
    <motor name="dof_left_ankle_02_ctrl" joint="dof_left_ankle_02" class="robstride_02" />
  </actuator>

  <contact>
    <exclude body1="Torso_Side_Right" body2="KC_C_104R_PitchHardstopDriven" />
    <exclude body1="Torso_Side_Right" body2="imu" />
    <exclude body1="Torso_Side_Right" body2="KC_C_104L_PitchHardstopDriven" />
    <exclude body1="Torso_Side_Right" body2="KC_D_102R_R_Hip_Yoke_Drive" />
    <exclude body1="Torso_Side_Right" body2="KC_D_102L_L_Hip_Yoke_Drive" />
    <exclude body1="KC_C_104R_PitchHardstopDriven" body2="RS03_3" />
    <exclude body1="KC_D_102R_R_Hip_Yoke_Drive" body2="RS03_4" />
    <exclude body1="KC_D_102L_L_Hip_Yoke_Drive" body2="RS03_5" />
    <exclude body1="KC_C_104L_PitchHardstopDriven" body2="RS03_6" />
    <exclude body1="RS03_3" body2="KC_C_202R" />
    <exclude body1="RS03_6" body2="KC_C_202L" />
    <exclude body1="RS03_4" body2="KC_D_301R_R_Femur_Lower_Drive" />
    <exclude body1="RS03_5" body2="KC_D_301L_L_Femur_Lower_Drive" />
    <exclude body1="KC_C_202R" body2="KC_C_401R_R_UpForearmDrive" />
    <exclude body1="KC_C_202L" body2="KC_C_401L_L_UpForearmDrive" />
    <exclude body1="KC_D_301R_R_Femur_Lower_Drive" body2="KC_D_401R_R_Shin_Drive" />
    <exclude body1="KC_D_301L_L_Femur_Lower_Drive" body2="KC_D_401L_L_Shin_Drive" />
    <exclude body1="KC_C_401R_R_UpForearmDrive" body2="KB_C_501X_Right_Bayonet_Adapter_Hard_Stop" />
    <exclude body1="KC_C_401L_L_UpForearmDrive" body2="KB_C_501X_Left_Bayonet_Adapter_Hard_Stop" />
    <exclude body1="KC_D_401R_R_Shin_Drive" body2="KB_D_501R_R_LEG_FOOT" />
    <exclude body1="KC_D_401L_L_Shin_Drive" body2="KB_D_501L_L_LEG_FOOT" />
  </contact>

  <sensor>
    <framepos name="base_site_pos" objtype="site" objname="base_site" />
    <framequat name="base_site_quat" objtype="site" objname="base_site" />
    <framelinvel name="base_site_linvel" objtype="site" objname="base_site" />
    <frameangvel name="base_site_angvel" objtype="site" objname="base_site" />
    <velocimeter name="base_site_vel" site="base_site" />
    <accelerometer name="imu_acc" site="imu_site" noise="0.01" />
    <gyro name="imu_gyro" site="imu_site" noise="0.01" />
    <magnetometer name="imu_mag" site="imu_site" noise="0.05" />
    <framepos name="imu_site_pos" objtype="site" objname="imu_site" />
    <framequat name="imu_site_quat" objtype="site" objname="imu_site" />
    <framelinvel name="imu_site_linvel" objtype="site" objname="imu_site" />
    <frameangvel name="imu_site_angvel" objtype="site" objname="imu_site" />
    <velocimeter name="imu_site_vel" site="imu_site" />
    <force name="left_foot_force" site="left_foot" />
    <force name="right_foot_force" site="right_foot" />
    <touch name="left_foot_touch" site="left_foot" />
    <touch name="right_foot_touch" site="right_foot" />
  </sensor>
</mujoco>